Workbook

Sheet RAW DATA
A1: Emiten | B1: Tahun | C1: Current Assets | D1: Fixed Assets (Non CA) | E1: Total Assets | F1: Current Liabilities | G1: Total Liabilities | H1: Total Equity | I1: Sales Revenue | J1: EBIT (Operating Profit) | K1: Taxation (Tax Expenses) | L1: Net Income (Profit For the Year) | M1: Depreciation (Depreciation Expense) | N1: Year Listed | O1: AGE
A2: APLN | B2: 2019 | I2: 3792475607000
B3: 2020 | C3: 11676576495000 | D3: 18714783461000 | E3: 30391359956000 | F3: 6158911981000 | G3: 19036134922000 | H3: 11355225034000 | I3: 4956324700000 | J3: 1254480460000 | K3: 214555110000 | L3: 180144690000 | M3: 188737037000 | N3: 2010 | O3: =B3-N3 -> 10
B4: 2021 | C4: 11958891761000 | D4: 17652219432000 | E4: 29611111193000 | F4: 7314345544000 | G4: 19071333513000 | H4: 10539777680000 | I4: 4256245345000 | J4: 554113280000 | K4: 183387410000 | L4: -485227632000 | M4: 285912302000 | N4: 2010 | O4: =B4-N4 -> 11
B5: 2022 | C5: 11303386748000 | D5: 17314394993000 | E5: 28617781741000 | F5: 5771555207000 | G5: 16148220661000 | H5: 12469561080000 | I5: 8663824988000 | J5: 3768403830000 | K5: 312823830000 | L5: 2268910393000 | M5: 251429916000 | N5: 2010 | O5: =B5-N5 -> 12
B6: 2023 | C6: 11110900726000 | D6: 17216650886000 | E6: 28327551612000 | F6: 8538370071000 | G6: 14876147126000 | H6: 13451404486000 | I6: 4676651899000 | J6: 943423270000 | K6: 200314247000 | L6: 1164518767000 | M6: 242599591000 | N6: 2010 | O6: =B6-N6 -> 13
B7: 2024 | C7: 10864722185000 | D7: 15254955241000 | E7: 26119677426000 | F7: 4465148646000 | G7: 12335995789000 | H7: 13783681637000 | I7: 5576757087000 | J7: 1405599949000 | K7: 202679417000 | L7: 770526340000 | M7: 207349317000 | N7: 2010 | O7: =B7-N7 -> 14
A8: ASRI | B8: 2019 | I8: 3475677175000
B9: 2020 | C9: 2156001152000 | D9: 19070813719000 | E9: 21226814871000 | F9: 3198161431000 | G9: 11840666961000 | H9: 9386147910000 | I9: 1413251960000 | J9: 172780330000 | K9: 113380980000 | L9: -1036617870000 | M9: 104947860000 | N9: 2007 | O9: =B9-N9 -> 13
B10: 2021 | C10: 3034403543000 | D10: 18899571171000 | E10: 21933974714000 | F10: 3633263428000 | G10: 12397883478000 | H10: 9536091236000 | I10: 2847323720000 | J10: 1109773040000 | K10: 87131850000 | L10: 142928790000 | M10: 62520700000 | N10: 2007 | O10: =B10-N10 -> 14
B11: 2022 | C11: 3636178310000 | D11: 18662746961000 | E11: 22298925271000 | F11: 3717703477000 | G11: 11656300706000 | H11: 10642624565000 | I11: 4493531260000 | J11: 2139736770000 | K11: 123536910000 | L11: 1098364940000 | M11: 61418598000 | N11: 2007 | O11: =B11-N11 -> 15
B12: 2023 | C12: 2905301328000 | D12: 19330935536000 | E12: 22236236864000 | F12: 3688162066000 | G12: 10965051102000 | H12: 11271185762000 | I12: 3956015546000 | J12: 1667193500000 | K12: 129534290000 | L12: 637639854000 | M12: 49482744000 | N12: 2007 | O12: =B12-N12 -> 16
B13: 2024 | C13: 2832227835000 | D13: 19186803598000 | E13: 22019031433000 | F13: 3704391625000 | G13: 10683291993000 | H13: 11335739440000 | I13: 3433337156000 | J13: 1239889270000 | K13: 105105660000 | L13: 65136557000 | M13: 53956088000 | N13: 2007 | O13: =B13-N13 -> 17
A14: BAPA | B14: 2019 | I14: 24233788566
B15: 2020 | C15: =107744636327-82118871642 -> 25625764685 | D15: 116681006344 | E15: 142306771029 | F15: 7445381494 | G15: 8098923359 | H15: 134207847670 | I15: 9518983284 | J15: -2416160000 | K15: 378130000 | L15: -3737826580 | M15: 490282306 | N15: 2008 | O15: =B15-N15 -> 12
B16: 2021 | C16: 24281768224 | D16: 115289230111 | E16: 139570998335 | F16: 6792627578 | G16: 7171085839 | H16: 132399912496 | I16: 6194779683 | J16: -1708580000 | K16: 284410000 | L16: -2052255452 | M16: 490840486 | N16: 2008 | O16: =B16-N16 -> 13
B17: 2022 | C17: 22845370858 | D17: 112588642630 | E17: 135434013488 | F17: 6382787788 | G17: 6589092293 | H17: 128844921195 | I17: 3716043983 | J17: -3389301025 | K17: 209046878 | L17: -3712072464 | M17: 391354364 | N17: 2008 | O17: =B17-N17 -> 14
B18: 2023 | C18: 23288555973 | D18: 111573770722 | E18: 134862326695 | F18: 8585199688 | G18: 9062277504 | H18: 125800049191 | I18: 8119901265 | J18: -2331594337 | K18: 335560000 | L18: -2857333912 | M18: 511334453 | N18: 2008 | O18: =B18-N18 -> 15
B19: 2024 | C19: 23781119616 | D19: 108899900112 | E19: 132681019728 | F19: 10764200911 | G19: 12058589498 | H19: 120622430230 | I19: 4066108299 | J19: -4171546149 | K19: 164610000 | L19: -4572611851 | M19: 475830398 | N19: 2008 | O19: =B19-N19 -> 16
A20: BCIP | B20: 2019 | I20: 131094399577
B21: 2020 | C21: 395767984972 | D21: 513496477691 | E21: 909264462663 | F21: 308300895925 | G21: 462672453925 | H21: 446592008738 | I21: 73155228143 | J21: -4159761783 | K21: 1617220000 | L21: 12990820000 | M21: 2322249697 | N21: 2009 | O21: =B21-N21 -> 11
B22: 2021 | C22: 347736855343 | D22: 539336210053 | E22: 887073065396 | F22: 101144035422 | G22: 440374923594 | H22: 446698141802 | I22: 60409520263 | J22: -2724931140 | K22: 3408850000 | L22: 124179366 | M22: 2917343445 | N22: 2009 | O22: =B22-N22 -> 12
B23: 2022 | C23: 366321332034 | D23: 517713181088 | E23: 884034513122 | F23: 81907072930 | G23: 420288826352 | H23: 463745686769 | I23: 93742996267 | J23: 12378007493 | K23: 4138710000 | L23: 17063851989 | M23: 2271376466 | N23: 2009 | O23: =B23-N23 -> 13
B24: 2023 | C24: 380086878947 | D24: 530545675686 | E24: 910632554632 | F24: 84501811522 | G24: 429633626606 | H24: 480998928026 | I24: 94302986070 | J24: 11321818102 | K24: 3855150000 | L24: 17290964462 | M24: 2161799094 | N24: 2009 | O24: =B24-N24 -> 14
B25: 2024 | C25: 358863132348 | D25: 556635875773 | E25: 915499008121 | F25: 102828240347 | G25: 421739606444 | H25: 493759401677 | I25: 100002191228 | J25: 8298864109 | K25: 4014790000 | L25: 15271683642 | M25: 2686557561 | N25: 2009 | O25: =B25-N25 -> 15
A26: BEST | B26: 2019 | I26: 950545546999
B27: 2020 | C27: 2722827270198 | D27: 3559352959534 | E27: 6282180229732 | F27: 258669858995 | G27: 1925523126081 | H27: 4356657103651 | I27: 242320700845 | J27: 22157030000 | K27: 5817220000 | L27: -115219635076 | M27: 15870787108 | N27: 2012 | O27: =B27-N27 -> 8
B28: 2021 | C28: 2512714351541 | D28: 3533498033871 | E28: 6046212385412 | F28: 432585170220 | G28: 1752315039995 | H28: 4293897345417 | I28: 229835755986 | J28: 29479890000 | K28: 6142760000 | L28: -71095023263 | M28: 14475488334 | N28: 2012 | O28: =B28-N28 -> 9
B29: 2022 | C29: 2587148796402 | D29: 3491320112624 | E29: 6078468909026 | F29: 279952124627 | G29: 1749964841755 | H29: 4328504067271 | I29: 542834010731 | J29: 217390750000 | K29: 13683940000 | L29: 33729572546 | M29: 13411716896 | N29: 2012 | O29: =B29-N29 -> 10
B30: 2023 | C30: 2429482806528 | D30: 3510621542592 | E30: 5940104349120 | F30: 242206129142 | G30: 1572306529495 | H30: 4367797819625 | I30: 544314875513 | J30: 226477640000 | K30: 13096340000 | L30: 39528179905 | M30: 13981686993 | N30: 2012 | O30: =B30-N30 -> 11
B31: 2024 | C31: 2285508367613 | D31: 3541700062485 | E31: 5827208430098 | F31: 230503232839 | G31: 1401047153697 | H31: 4426161276401 | I31: 457589770772 | J31: 172045640000 | K31: 13403550000 | L31: 58582277467 | M31: 14014116310 | N31: 2012 | O31: =B31-N31 -> 12
A32: BIPP | B32: 2019 | I32: 359062749459
B33: 2020 | C33: 987418770826 | D33: 1139106559488 | E33: 2126525330314 | F33: 378439919105 | G33: 919581439010 | H33: 1206943891304 | I33: 529839404669 | J33: 143700277536 | K33: 16884070000 | L33: 94063090000 | M33: 7111076320 | N33: 1995 | O33: =B33-N33 -> 25
B34: 2021 | C34: 715590607726 | D34: 1329692580492 | E34: 2045283188218 | F34: 418513498673 | G34: 942012364746 | H34: 1103270823472 | I34: 293991355499 | J34: 67416473305 | K34: 12086260000 | L34: 19556640000 | M34: 6846229884 | N34: 1995 | O34: =B34-N34 -> 26
B35: 2022 | C35: 573208654112 | D35: 1315127852645 | E35: 1888336506757 | F35: 247729876368 | G35: 806384409413 | H35: 1081952097344 | I35: 327320863485 | J35: 77290508572 | K35: 12812350000 | L35: 25273690000 | M35: 7988936242 | N35: 1995 | O35: =B35-N35 -> 27
B36: 2023 | C36: 509753644372 | D36: 1435570222861 | E36: 1945323867233 | F36: 257412101987 | G36: 891896202079 | H36: 1053427665154 | I36: 264064990351 | J36: 54739339966 | K36: 9463760000 | L36: -4472990784 | M36: 10509468325 | N36: 1995 | O36: =B36-N36 -> 28
B37: 2024 | C37: 415752030680 | D37: 1445259166357 | E37: 1861011197037 | F37: 228206979554 | G37: 837870148178 | H37: 1023141048859 | I37: 258557430709 | J37: 56178512167 | K37: 15698040000 | L37: -6450817152 | M37: 11198281375 | N37: 1995 | O37: =B37-N37 -> 29
A38: BKDP | B38: 2019 | I38: 35174135994
B39: 2020 | C39: 86926323534 | D39: 703913851987 | E39: 790840175521 | F39: 171661406293 | G39: 309509265589 | H39: 481330909932 | I39: 19558738651 | J39: -28936032740 | K39: 1248580000 | L39: -31050114021 | M39: 3058630965 | N39: 2007 | O39: =B39-N39 -> 13
B40: 2021 | C40: 82564049560 | D40: 691575548789 | E40: 774139598349 | F40: 108482187823 | G40: 327575792987 | H40: 446563805362 | I40: 23401842549 | J40: -28529682149 | K40: 2250300000 | L40: -36260265843 | M40: 1381646874 | N40: 2007 | O40: =B40-N40 -> 14
...

Sheet HASIL PERHITUNGAN
A1: Emiten | B1: Tahun | C1: DER | D1: TDR | E1: ROE | F1: TAN | G1: LIQ | H1: GRW | I1: SIZ | J1: TAX | K1: AGE | L1: NDTS
A2: APLN | B2: 2020 | C2: ='RAW DATA'!G3/'RAW DATA'!H3 -> 1.6764208 | D2: ='RAW DATA'!G3/'RAW DATA'!E3 -> 0.62636667 | E2: ='RAW DATA'!L3/'RAW DATA'!H3 -> 0.015864476 | F2: ='RAW DATA'!D3/'RAW DATA'!E3 -> 0.61579289 | G2: ='RAW DATA'!C3/'RAW DATA'!F3 -> 1.895883 | H2: =('RAW DATA'!I3-'RAW DATA'!I2)/'RAW DATA'!I2 -> 0.30688374 | I2: =LN('RAW DATA'!E3) -> 31.045179 | J2: ='RAW DATA'!K3/'RAW DATA'!J3 -> 0.17103105 | K2: =LN('RAW DATA'!O3) -> 2.3025851 | L2: ='RAW DATA'!M3/'RAW DATA'!E3 -> 0.0062102202
A3: APLN | B3: 2021 | C3: ='RAW DATA'!G4/'RAW DATA'!H4 -> 1.8094626 | D3: ='RAW DATA'!G4/'RAW DATA'!E4 -> 0.64406004 | E3: ='RAW DATA'!L4/'RAW DATA'!H4 -> -0.046037748 | F3: ='RAW DATA'!D4/'RAW DATA'!E4 -> 0.59613499 | G3: ='RAW DATA'!C4/'RAW DATA'!F4 -> 1.6349914 | H3: =('RAW DATA'!I4-'RAW DATA'!I3)/'RAW DATA'!I3 -> -0.1412497 | I3: =LN('RAW DATA'!E4) -> 31.019171 | J3: ='RAW DATA'!K4/'RAW DATA'!J4 -> 0.33095653 | K3: =LN('RAW DATA'!O4) -> 2.3978953 | L3: ='RAW DATA'!M4/'RAW DATA'!E4 -> 0.0096555749
A4: APLN | B4: 2022 | C4: ='RAW DATA'!G5/'RAW DATA'!H5 -> 1.2950112 | D4: ='RAW DATA'!G5/'RAW DATA'!E5 -> 0.56427227 | E4: ='RAW DATA'!L5/'RAW DATA'!H5 -> 0.18195591 | F4: ='RAW DATA'!D5/'RAW DATA'!E5 -> 0.60502226 | G4: ='RAW DATA'!C5/'RAW DATA'!F5 -> 1.9584646 | H4: =('RAW DATA'!I5-'RAW DATA'!I4)/'RAW DATA'!I4 -> 1.0355558 | I4: =LN('RAW DATA'!E5) -> 30.985049 | J4: ='RAW DATA'!K5/'RAW DATA'!J5 -> 0.08301229 | K4: =LN('RAW DATA'!O5) -> 2.4849066 | L4: ='RAW DATA'!M5/'RAW DATA'!E5 -> 0.0087857933
A5: APLN | B5: 2023 | C5: ='RAW DATA'!G6/'RAW DATA'!H6 -> 1.1059178 | D5: ='RAW DATA'!G6/'RAW DATA'!E6 -> 0.52514765 | E5: ='RAW DATA'!L6/'RAW DATA'!H6 -> 0.086572281 | F5: ='RAW DATA'!D6/'RAW DATA'!E6 -> 0.60777052 | G5: ='RAW DATA'!C6/'RAW DATA'!F6 -> 1.3012906 | H5: =('RAW DATA'!I6-'RAW DATA'!I5)/'RAW DATA'!I5 -> -0.46020933 | I5: =LN('RAW DATA'!E6) -> 30.974856 | J5: ='RAW DATA'!K6/'RAW DATA'!J6 -> 0.21232702 | K5: =LN('RAW DATA'!O6) -> 2.5649494 | L5: ='RAW DATA'!M6/'RAW DATA'!E6 -> 0.0085640861
A6: APLN | B6: 2024 | C6: ='RAW DATA'!G7/'RAW DATA'!H7 -> 0.89497103 | D6: ='RAW DATA'!G7/'RAW DATA'!E7 -> 0.47228745 | E6: ='RAW DATA'!L7/'RAW DATA'!H7 -> 0.055901345 | F6: ='RAW DATA'!D7/'RAW DATA'!E7 -> 0.58404072 | G6: ='RAW DATA'!C7/'RAW DATA'!F7 -> 2.4332274 | H6: =('RAW DATA'!I7-'RAW DATA'!I6)/'RAW DATA'!I6 -> 0.19246786 | I6: =LN('RAW DATA'!E7) -> 30.89371 | J6: ='RAW DATA'!K7/'RAW DATA'!J7 -> 0.14419424 | K6: =LN('RAW DATA'!O7) -> 2.6390573 | L6: ='RAW DATA'!M7/'RAW DATA'!E7 -> 0.0079384333
A7: ASRI | B7: 2020 | C7: ='RAW DATA'!G9/'RAW DATA'!H9 -> 1.2615044 | D7: ='RAW DATA'!G9/'RAW DATA'!E9 -> 0.55781647 | E7: ='RAW DATA'!L9/'RAW DATA'!H9 -> -0.11044125 | F7: ='RAW DATA'!D9/'RAW DATA'!E9 -> 0.8984303 | G7: ='RAW DATA'!C9/'RAW DATA'!F9 -> 0.67413769 | H7: =('RAW DATA'!I9-'RAW DATA'!I8)/'RAW DATA'!I8 -> -0.59338803 | I7: =LN('RAW DATA'!E9) -> 30.686286 | J7: ='RAW DATA'!K9/'RAW DATA'!J9 -> 0.65621463 | K7: =LN('RAW DATA'!O9) -> 2.5649494 | L7: ='RAW DATA'!M9/'RAW DATA'!E9 -> 0.0049441172
A8: ASRI | B8: 2021 | C8: ='RAW DATA'!G10/'RAW DATA'!H10 -> 1.3001012 | D8: ='RAW DATA'!G10/'RAW DATA'!E10 -> 0.56523652 | E8: ='RAW DATA'!L10/'RAW DATA'!H10 -> 0.014988194 | F8: ='RAW DATA'!D10/'RAW DATA'!E10 -> 0.86165738 | G8: ='RAW DATA'!C10/'RAW DATA'!F10 -> 0.83517301 | H8: =('RAW DATA'!I10-'RAW DATA'!I9)/'RAW DATA'!I9 -> 1.0147318 | I8: =LN('RAW DATA'!E10) -> 30.719058 | J8: ='RAW DATA'!K10/'RAW DATA'!J10 -> 0.078513216 | K8: =LN('RAW DATA'!O10) -> 2.6390573 | L8: ='RAW DATA'!M10/'RAW DATA'!E10 -> 0.0028504045
A9: ASRI | B9: 2022 | C9: ='RAW DATA'!G11/'RAW DATA'!H11 -> 1.0952468 | D9: ='RAW DATA'!G11/'RAW DATA'!E11 -> 0.52272926 | E9: ='RAW DATA'!L11/'RAW DATA'!H11 -> 0.10320433 | F9: ='RAW DATA'!D11/'RAW DATA'!E11 -> 0.83693482 | G9: ='RAW DATA'!C11/'RAW DATA'!F11 -> 0.97807109 | H9: =('RAW DATA'!I11-'RAW DATA'!I10)/'RAW DATA'!I10 -> 0.5781596 | I9: =LN('RAW DATA'!E11) -> 30.73556 | J9: ='RAW DATA'!K11/'RAW DATA'!J11 -> 0.05773463 | K9: =LN('RAW DATA'!O11) -> 2.7080502 | L9: ='RAW DATA'!M11/'RAW DATA'!E11 -> 0.00275433
A10: ASRI | B10: 2023 | C10: ='RAW DATA'!G12/'RAW DATA'!H12 -> 0.97283918 | D10: ='RAW DATA'!G12/'RAW DATA'!E12 -> 0.49311631 | E10: ='RAW DATA'!L12/'RAW DATA'!H12 -> 0.056572562 | F10: ='RAW DATA'!D12/'RAW DATA'!E12 -> 0.86934384 | G10: ='RAW DATA'!C12/'RAW DATA'!F12 -> 0.78773689 | H10: =('RAW DATA'!I12-'RAW DATA'!I11)/'RAW DATA'!I11 -> -0.11961989 | I10: =LN('RAW DATA'!E12) -> 30.732744 | J10: ='RAW DATA'!K12/'RAW DATA'!J12 -> 0.077696014 | K10: =LN('RAW DATA'!O12) -> 2.7725887 | L10: ='RAW DATA'!M12/'RAW DATA'!E12 -> 0.0022253201
A11: ASRI | B11: 2024 | C11: ='RAW DATA'!G13/'RAW DATA'!H13 -> 0.94244333 | D11: ='RAW DATA'!G13/'RAW DATA'!E13 -> 0.48518447 | E11: ='RAW DATA'!L13/'RAW DATA'!H13 -> 0.0057461233 | F11: ='RAW DATA'!D13/'RAW DATA'!E13 -> 0.87137364 | G11: ='RAW DATA'!C13/'RAW DATA'!F13 -> 0.76455951 | H11: =('RAW DATA'!I13-'RAW DATA'!I12)/'RAW DATA'!I12 -> -0.13212243 | I11: =LN('RAW DATA'!E13) -> 30.722928 | J11: ='RAW DATA'!K13/'RAW DATA'!J13 -> 0.084770199 | K11: =LN('RAW DATA'!O13) -> 2.8332133 | L11: ='RAW DATA'!M13/'RAW DATA'!E13 -> 0.0024504297
A12: BAPA | B12: 2020 | C12: ='RAW DATA'!G15/'RAW DATA'!H15 -> 0.060346124 | D12: ='RAW DATA'!G15/'RAW DATA'!E15 -> 0.056911722 | E12: ='RAW DATA'!L15/'RAW DATA'!H15 -> -0.027851028 | F12: ='RAW DATA'!D15/'RAW DATA'!E15 -> 0.81992589 | G12: ='RAW DATA'!C15/'RAW DATA'!F15 -> 3.4418337 | H12: =('RAW DATA'!I15-'RAW DATA'!I14)/'RAW DATA'!I14 -> -0.60720202 | I12: =LN('RAW DATA'!E15) -> 25.681251 | J12: ='RAW DATA'!K15/'RAW DATA'!J15 -> -0.1565004 | K12: =LN('RAW DATA'!O15) -> 2.4849066 | L12: ='RAW DATA'!M15/'RAW DATA'!E15 -> 0.0034452493
A13: BAPA | B13: 2021 | C13: ='RAW DATA'!G16/'RAW DATA'!H16 -> 0.054162316 | D13: ='RAW DATA'!G16/'RAW DATA'!E16 -> 0.051379484 | E13: ='RAW DATA'!L16/'RAW DATA'!H16 -> -0.015500429 | F13: ='RAW DATA'!D16/'RAW DATA'!E16 -> 0.82602569 | G13: ='RAW DATA'!C16/'RAW DATA'!F16 -> 3.5747239 | H13: =('RAW DATA'!I16-'RAW DATA'!I15)/'RAW DATA'!I15 -> -0.34921835 | I13: =LN('RAW DATA'!E16) -> 25.661839 | J13: ='RAW DATA'!K16/'RAW DATA'!J16 -> -0.16645987 | K13: =LN('RAW DATA'!O16) -> 2.5649494 | L13: ='RAW DATA'!M16/'RAW DATA'!E16 -> 0.0035167799
A14: BAPA | B14: 2022 | C14: ='RAW DATA'!G17/'RAW DATA'!H17 -> 0.051139713 | D14: ='RAW DATA'!G17/'RAW DATA'!E17 -> 0.04865168 | E14: ='RAW DATA'!L17/'RAW DATA'!H17 -> -0.02881039 | F14: ='RAW DATA'!D17/'RAW DATA'!E17 -> 0.83131733 | G14: ='RAW DATA'!C17/'RAW DATA'!F17 -> 3.5792152 | H14: =('RAW DATA'!I17-'RAW DATA'!I16)/'RAW DATA'!I16 -> -0.40013299 | I14: =LN('RAW DATA'!E17) -> 25.63175 | J14: ='RAW DATA'!K17/'RAW DATA'!J17 -> -0.061678463 | K14: =LN('RAW DATA'!O17) -> 2.6390573 | L14: ='RAW DATA'!M17/'RAW DATA'!E17 -> 0.0028896313
A15: BAPA | B15: 2023 | C15: ='RAW DATA'!G18/'RAW DATA'!H18 -> 0.072037154 | D15: ='RAW DATA'!G18/'RAW DATA'!E18 -> 0.067196509 | E15: ='RAW DATA'!L18/'RAW DATA'!H18 -> -0.022713297 | F15: ='RAW DATA'!D18/'RAW DATA'!E18 -> 0.82731607 | G15: ='RAW DATA'!C18/'RAW DATA'!F18 -> 2.71264 | H15: =('RAW DATA'!I18-'RAW DATA'!I17)/'RAW DATA'!I17 -> 1.1850929 | I15: =LN('RAW DATA'!E18) -> 25.62752 | J15: ='RAW DATA'!K18/'RAW DATA'!J18 -> -0.14391869 | K15: =LN('RAW DATA'!O18) -> 2.7080502 | L15: ='RAW DATA'!M18/'RAW DATA'!E18 -> 0.0037915292
A16: BAPA | B16: 2024 | C16: ='RAW DATA'!G19/'RAW DATA'!H19 -> 0.099969711 | D16: ='RAW DATA'!G19/'RAW DATA'!E19 -> 0.090884058 | E16: ='RAW DATA'!L19/'RAW DATA'!H19 -> -0.037908471 | F16: ='RAW DATA'!D19/'RAW DATA'!E19 -> 0.82076472 | G16: ='RAW DATA'!C19/'RAW DATA'!F19 -> 2.2092787 | H16: =('RAW DATA'!I19-'RAW DATA'!I18)/'RAW DATA'!I18 -> -0.49924166 | I16: =LN('RAW DATA'!E19) -> 25.611214 | J16: ='RAW DATA'!K19/'RAW DATA'!J19 -> -0.039460189 | K16: =LN('RAW DATA'!O19) -> 2.7725887 | L16: ='RAW DATA'!M19/'RAW DATA'!E19 -> 0.0035862733
A17: BCIP | B17: 2020 | C17: ='RAW DATA'!G21/'RAW DATA'!H21 -> 1.036007 | D17: ='RAW DATA'!G21/'RAW DATA'!E21 -> 0.50884256 | E17: ='RAW DATA'!L21/'RAW DATA'!H21 -> 0.029088787 | F17: ='RAW DATA'!D21/'RAW DATA'!E21 -> 0.56473831 | G17: ='RAW DATA'!C21/'RAW DATA'!F21 -> 1.2837069 | H17: =('RAW DATA'!I21-'RAW DATA'!I20)/'RAW DATA'!I20 -> -0.44196527 | I17: =LN('RAW DATA'!E21) -> 27.535902 | J17: ='RAW DATA'!K21/'RAW DATA'!J21 -> -0.38877707 | K17: =LN('RAW DATA'!O21) -> 2.3978953 | L17: ='RAW DATA'!M21/'RAW DATA'!E21 -> 0.0025539871
A18: BCIP | B18: 2021 | C18: ='RAW DATA'!G22/'RAW DATA'!H22 -> 0.98584454 | D18: ='RAW DATA'!G22/'RAW DATA'!E22 -> 0.49643591 | E18: ='RAW DATA'!L22/'RAW DATA'!H22 -> 0.00027799392 | F18: ='RAW DATA'!D22/'RAW DATA'!E22 -> 0.60799525 | G18: ='RAW DATA'!C22/'RAW DATA'!F22 -> 3.4380362 | H18: =('RAW DATA'!I22-'RAW DATA'!I21)/'RAW DATA'!I21 -> -0.17422826 | I18: =LN('RAW DATA'!E22) -> 27.511193 | J18: ='RAW DATA'!K22/'RAW DATA'!J22 -> -1.2509857 | K18: =LN('RAW DATA'!O22) -> 2.4849066 | L18: ='RAW DATA'!M22/'RAW DATA'!E22 -> 0.0032887296
A19: BCIP | B19: 2022 | C19: ='RAW DATA'!G23/'RAW DATA'!H23 -> 0.90629161 | D19: ='RAW DATA'!G23/'RAW DATA'!E23 -> 0.47542129 | E19: ='RAW DATA'!L23/'RAW DATA'!H23 -> 0.03679571 | F19: ='RAW DATA'!D23/'RAW DATA'!E23 -> 0.58562553 | G19: ='RAW DATA'!C23/'RAW DATA'!F23 -> 4.4724017 | H19: =('RAW DATA'!I23-'RAW DATA'!I22)/'RAW DATA'!I22 -> 0.55179177 | I19: =LN('RAW DATA'!E23) -> 27.507762 | J19: ='RAW DATA'!K23/'RAW DATA'!J23 -> 0.33435995 | K19: =LN('RAW DATA'!O23) -> 2.5649494 | L19: ='RAW DATA'!M23/'RAW DATA'!E23 -> 0.0025693301
A20: BCIP | B20: 2023 | C20: ='RAW DATA'!G24/'RAW DATA'!H24 -> 0.89321119 | D20: ='RAW DATA'!G24/'RAW DATA'!E24 -> 0.47179691 | E20: ='RAW DATA'!L24/'RAW DATA'!H24 -> 0.035948031 | F20: ='RAW DATA'!D24/'RAW DATA'!E24 -> 0.58261224 | G20: ='RAW DATA'!C24/'RAW DATA'!F24 -> 4.4979731 | H20: =('RAW DATA'!I24-'RAW DATA'!I23)/'RAW DATA'!I23 -> 0.0059736708 | I20: =LN('RAW DATA'!E24) -> 27.537405 | J20: ='RAW DATA'!K24/'RAW DATA'!J24 -> 0.34050627 | K20: =LN('RAW DATA'!O24) -> 2.6390573 | L20: ='RAW DATA'!M24/'RAW DATA'!E24 -> 0.0023739532
A21: BCIP | B21: 2024 | C21: ='RAW DATA'!G25/'RAW DATA'!H25 -> 0.8541399 | D21: ='RAW DATA'!G25/'RAW DATA'!E25 -> 0.46066637 | E21: ='RAW DATA'!L25/'RAW DATA'!H25 -> 0.030929403 | F21: ='RAW DATA'!D25/'RAW DATA'!E25 -> 0.60801363 | G21: ='RAW DATA'!C25/'RAW DATA'!F25 -> 3.4899278 | H21: =('RAW DATA'!I25-'RAW DATA'!I24)/'RAW DATA'!I24 -> 0.060435044 | I21: =LN('RAW DATA'!E25) -> 27.542735 | J21: ='RAW DATA'!K25/'RAW DATA'!J25 -> 0.48377585 | K21: =LN('RAW DATA'!O25) -> 2.7080502 | L21: ='RAW DATA'!M25/'RAW DATA'!E25 -> 0.0029345281
A22: BEST | B22: 2020 | C22: ='RAW DATA'!G27/'RAW DATA'!H27 -> 0.44197261 | D22: ='RAW DATA'!G27/'RAW DATA'!E27 -> 0.30650555 | E22: ='RAW DATA'!L27/'RAW DATA'!H27 -> -0.026446799 | F22: ='RAW DATA'!D27/'RAW DATA'!E27 -> 0.56657925 | G22: ='RAW DATA'!C27/'RAW DATA'!F27 -> 10.526264 | H22: =('RAW DATA'!I27-'RAW DATA'!I26)/'RAW DATA'!I26 -> -0.74507197 | I22: =LN('RAW DATA'!E27) -> 29.468738 | J22: ='RAW DATA'!K27/'RAW DATA'!J27 -> 0.26254512 | K22: =LN('RAW DATA'!O27) -> 2.0794415 | L22: ='RAW DATA'!M27/'RAW DATA'!E27 -> 0.0025263183
A23: BEST | B23: 2021 | C23: ='RAW DATA'!G28/'RAW DATA'!H28 -> 0.4080943 | D23: ='RAW DATA'!G28/'RAW DATA'!E28 -> 0.28982029 | E23: ='RAW DATA'!L28/'RAW DATA'!H28 -> -0.016557225 | F23: ='RAW DATA'!D28/'RAW DATA'!E28 -> 0.58441514 | G23: ='RAW DATA'!C28/'RAW DATA'!F28 -> 5.8086003 | H23: =('RAW DATA'!I28-'RAW DATA'!I27)/'RAW DATA'!I27 -> -0.051522403 | I23: =LN('RAW DATA'!E28) -> 29.430453 | J23: ='RAW DATA'!K28/'RAW DATA'!J28 -> 0.2083712 | K23: =LN('RAW DATA'!O28) -> 2.1972246 | L23: ='RAW DATA'!M28/'RAW DATA'!E28 -> 0.0023941416
A24: BEST | B24: 2022 | C24: ='RAW DATA'!G29/'RAW DATA'!H29 -> 0.4042886 | D24: ='RAW DATA'!G29/'RAW DATA'!E29 -> 0.28789566 | E24: ='RAW DATA'!L29/'RAW DATA'!H29 -> 0.0077924318 | F24: ='RAW DATA'!D29/'RAW DATA'!E29 -> 0.57437492 | G24: ='RAW DATA'!C29/'RAW DATA'!F29 -> 9.2413973 | H24: =('RAW DATA'!I29-'RAW DATA'!I28)/'RAW DATA'!I28 -> 1.3618345 | I24: =LN('RAW DATA'!E29) -> 29.435774 | J24: ='RAW DATA'!K29/'RAW DATA'!J29 -> 0.062946285 | K24: =LN('RAW DATA'!O29) -> 2.3025851 | L24: ='RAW DATA'!M29/'RAW DATA'!E29 -> 0.0022064301
A25: BEST | B25: 2023 | C25: ='RAW DATA'!G30/'RAW DATA'!H30 -> 0.35997695 | D25: ='RAW DATA'!G30/'RAW DATA'!E30 -> 0.26469342 | E25: ='RAW DATA'!L30/'RAW DATA'!H30 -> 0.0090499106 | F25: ='RAW DATA'!D30/'RAW DATA'!E30 -> 0.59100335 | G25: ='RAW DATA'!C30/'RAW DATA'!F30 -> 10.030641 | H25: =('RAW DATA'!I30-'RAW DATA'!I29)/'RAW DATA'!I29 -> 0.0027280251 | I25: =LN('RAW DATA'!E30) -> 29.412748 | J25: ='RAW DATA'!K30/'RAW DATA'!J30 -> 0.057826194 | K25: =LN('RAW DATA'!O30) -> 2.3978953 | L25: ='RAW DATA'!M30/'RAW DATA'!E30 -> 0.002353778
A26: BEST | B26: 2024 | C26: ='RAW DATA'!G31/'RAW DATA'!H31 -> 0.31653775 | D26: ='RAW DATA'!G31/'RAW DATA'!E31 -> 0.24043196 | E26: ='RAW DATA'!L31/'RAW DATA'!H31 -> 0.013235459 | F26: ='RAW DATA'!D31/'RAW DATA'!E31 -> 0.60778675 | G26: ='RAW DATA'!C31/'RAW DATA'!F31 -> 9.9152985 | H26: =('RAW DATA'!I31-'RAW DATA'!I30)/'RAW DATA'!I30 -> -0.15932893 | I26: =LN('RAW DATA'!E31) -> 29.393559 | J26: ='RAW DATA'!K31/'RAW DATA'!J31 -> 0.077906944 | K26: =LN('RAW DATA'!O31) -> 2.4849066 | L26: ='RAW DATA'!M31/'RAW DATA'!E31 -> 0.0024049451
A27: BIPP | B27: 2020 | C27: ='RAW DATA'!G33/'RAW DATA'!H33 -> 0.76190902 | D27: ='RAW DATA'!G33/'RAW DATA'!E33 -> 0.4324338 | E27: ='RAW DATA'!L33/'RAW DATA'!H33 -> 0.077934932 | F27: ='RAW DATA'!D33/'RAW DATA'!E33 -> 0.53566564 | G27: ='RAW DATA'!C33/'RAW DATA'!F33 -> 2.6091824 | H27: =('RAW DATA'!I33-'RAW DATA'!I32)/'RAW DATA'!I32 -> 0.47561786 | I27: =LN('RAW DATA'!E33) -> 28.38551 | J27: ='RAW DATA'!K33/'RAW DATA'!J33 -> 0.11749504 | K27: =LN('RAW DATA'!O33) -> 3.2188758 | L27: ='RAW DATA'!M33/'RAW DATA'!E33 -> 0.0033439885
A28: BIPP | B28: 2021 | C28: ='RAW DATA'!G34/'RAW DATA'!H34 -> 0.85383602 | D28: ='RAW DATA'!G34/'RAW DATA'!E34 -> 0.46057796 | E28: ='RAW DATA'!L34/'RAW DATA'!H34 -> 0.017726056 | F28: ='RAW DATA'!D34/'RAW DATA'!E34 -> 0.65012639 | G28: ='RAW DATA'!C34/'RAW DATA'!F34 -> 1.7098388 | H28: =('RAW DATA'!I34-'RAW DATA'!I33)/'RAW DATA'!I33 -> -0.4451312 | I28: =LN('RAW DATA'!E34) -> 28.346557 | J28: ='RAW DATA'!K34/'RAW DATA'!J34 -> 0.17927755 | K28: =LN('RAW DATA'!O34) -> 3.2580965 | L28: ='RAW DATA'!M34/'RAW DATA'!E34 -> 0.0033473261
A29: BIPP | B29: 2022 | C29: ='RAW DATA'!G35/'RAW DATA'!H35 -> 0.74530509 | D29: ='RAW DATA'!G35/'RAW DATA'!E35 -> 0.42703427 | E29: ='RAW DATA'!L35/'RAW DATA'!H35 -> 0.023359343 | F29: ='RAW DATA'!D35/'RAW DATA'!E35 -> 0.69644782 | G29: ='RAW DATA'!C35/'RAW DATA'!F35 -> 2.3138455 | H29: =('RAW DATA'!I35-'RAW DATA'!I34)/'RAW DATA'!I34 -> 0.11336901 | I29: =LN('RAW DATA'!E35) -> 28.266717 | J29: ='RAW DATA'!K35/'RAW DATA'!J35 -> 0.16576874 | K29: =LN('RAW DATA'!O35) -> 3.2958369 | L29: ='RAW DATA'!M35/'RAW DATA'!E35 -> 0.004230674
A30: BIPP | B30: 2023 | C30: ='RAW DATA'!G36/'RAW DATA'!H36 -> 0.84666108 | D30: ='RAW DATA'!G36/'RAW DATA'!E36 -> 0.45848212 | E30: ='RAW DATA'!L36/'RAW DATA'!H36 -> -0.00424613 | F30: ='RAW DATA'!D36/'RAW DATA'!E36 -> 0.7379595 | G30: ='RAW DATA'!C36/'RAW DATA'!F36 -> 1.9803018 | H30: =('RAW DATA'!I36-'RAW DATA'!I35)/'RAW DATA'!I35 -> -0.19325341 | I30: =LN('RAW DATA'!E36) -> 28.29645 | J30: ='RAW DATA'!K36/'RAW DATA'!J36 -> 0.17288773 | K30: =LN('RAW DATA'!O36) -> 3.3322045 | L30: ='RAW DATA'!M36/'RAW DATA'!E36 -> 0.005402426
A31: BIPP | B31: 2024 | C31: ='RAW DATA'!G37/'RAW DATA'!H37 -> 0.81891949 | D31: ='RAW DATA'!G37/'RAW DATA'!E37 -> 0.45022306 | E31: ='RAW DATA'!L37/'RAW DATA'!H37 -> -0.0063049148 | F31: ='RAW DATA'!D37/'RAW DATA'!E37 -> 0.77659886 | G31: ='RAW DATA'!C37/'RAW DATA'!F37 -> 1.82182 | H31: =('RAW DATA'!I37-'RAW DATA'!I36)/'RAW DATA'!I36 -> -0.020856834 | I31: =LN('RAW DATA'!E37) -> 28.252141 | J31: ='RAW DATA'!K37/'RAW DATA'!J37 -> 0.27943139 | K31: =LN('RAW DATA'!O37) -> 3.3672958 | L31: ='RAW DATA'!M37/'RAW DATA'!E37 -> 0.00601731
A32: BKDP | B32: 2020 | C32: ='RAW DATA'!G39/'RAW DATA'!H39 -> 0.64302803 | D32: ='RAW DATA'!G39/'RAW DATA'!E39 -> 0.39136766 | E32: ='RAW DATA'!L39/'RAW DATA'!H39 -> -0.064508872 | F32: ='RAW DATA'!D39/'RAW DATA'!E39 -> 0.89008358 | G32: ='RAW DATA'!C39/'RAW DATA'!F39 -> 0.50638245 | H32: =('RAW DATA'!I39-'RAW DATA'!I38)/'RAW DATA'!I38 -> -0.44394544 | I32: =LN('RAW DATA'!E39) -> 27.396362 | J32: ='RAW DATA'!K39/'RAW DATA'!J39 -> -0.043149661 | K32: =LN('RAW DATA'!O39) -> 2.5649494 | L32: ='RAW DATA'!M39/'RAW DATA'!E39 -> 0.0038675716
A33: BKDP | B33: 2021 | C33: ='RAW DATA'!G40/'RAW DATA'!H40 -> 0.73354757 | D33: ='RAW DATA'!G40/'RAW DATA'!E40 -> 0.42314822 | E33: ='RAW DATA'!L40/'RAW DATA'!H40 -> -0.081198399 | F33: ='RAW DATA'!D40/'RAW DATA'!E40 -> 0.89334734 | G33: ='RAW DATA'!C40/'RAW DATA'!F40 -> 0.76108393 | H33: =('RAW DATA'!I40-'RAW DATA'!I39)/'RAW DATA'!I39 -> 0.19649038 | I33: =LN('RAW DATA'!E40) -> 27.375018 | J33: ='RAW DATA'!K40/'RAW DATA'!J40 -> -0.078875747 | K33: =LN('RAW DATA'!O40) -> 2.6390573 | L33: ='RAW DATA'!M40/'RAW DATA'!E40 -> 0.0017847516
A34: BKDP | B34: 2022 | C34: ='RAW DATA'!G41/'RAW DATA'!H41 -> 0.83062913 | D34: ='RAW DATA'!G41/'RAW DATA'!E41 -> 0.45373971 | E34: ='RAW DATA'!L41/'RAW DATA'!H41 -> -0.079874799 | F34: ='RAW DATA'!D41/'RAW DATA'!E41 -> 0.91125283 | G34: ='RAW DATA'!C41/'RAW DATA'!F41 -> 0.51827355 | H34: =('RAW DATA'!I41-'RAW DATA'!I40)/'RAW DATA'!I40 -> 0.11255586 | I34: =LN('RAW DATA'!E41) -> 27.351968 | J34: ='RAW DATA'!K41/'RAW DATA'!J41 -> -0.12520481 | K34: =LN('RAW DATA'!O41) -> 2.7080502 | L34: ='RAW DATA'!M41/'RAW DATA'!E41 -> 0.0014389771
A35: BKDP | B35: 2023 | C35: ='RAW DATA'!G42/'RAW DATA'!H42 -> 0.98539888 | D35: ='RAW DATA'!G42/'RAW DATA'!E42 -> 0.49632288 | E35: ='RAW DATA'!L42/'RAW DATA'!H42 -> -0.090583578 | F35: ='RAW DATA'!D42/'RAW DATA'!E42 -> 0.92216362 | G35: ='RAW DATA'!C42/'RAW DATA'!F42 -> 0.37130931 | H35: =('RAW DATA'!I42-'RAW DATA'!I41)/'RAW DATA'!I41 -> 0.19878353 | I35: =LN('RAW DATA'!E42) -> 27.354264 | J35: ='RAW DATA'!K42/'RAW DATA'!J42 -> -0.10122786 | K35: =LN('RAW DATA'!O42) -> 2.7725887 | L35: ='RAW DATA'!M42/'RAW DATA'!E42 -> 0.0013752269
A36: BKDP | B36: 2024 | C36: ='RAW DATA'!G43/'RAW DATA'!H43 -> 1.1756089 | D36: ='RAW DATA'!G43/'RAW DATA'!E43 -> 0.54035855 | E36: ='RAW DATA'!L43/'RAW DATA'!H43 -> -0.10386882 | F36: ='RAW DATA'!D43/'RAW DATA'!E43 -> 0.92541704 | G36: ='RAW DATA'!C43/'RAW DATA'!F43 -> 0.30593421 | H36: =('RAW DATA'!I43-'RAW DATA'!I42)/'RAW DATA'!I42 -> -0.022135104 | I36: =LN('RAW DATA'!E43) -> 27.346328 | J36: ='RAW DATA'!K43/'RAW DATA'!J43 -> -0.10183739 | K36: =LN('RAW DATA'!O43) -> 2.8332133 | L36: ='RAW DATA'!M43/'RAW DATA'!E43 -> 0.0013493653
A37: BKSL | B37: 2020 | C37: ='RAW DATA'!G45/'RAW DATA'!H45 -> 0.79229781 | D37: ='RAW DATA'!G45/'RAW DATA'!E45 -> 0.44205701 | E37: ='RAW DATA'!L45/'RAW DATA'!H45 -> -0.05427282 | F37: ='RAW DATA'!D45/'RAW DATA'!E45 -> 0.75022189 | G37: ='RAW DATA'!C45/'RAW DATA'!F45 -> 1.4032123 | H37: =('RAW DATA'!I45-'RAW DATA'!I44)/'RAW DATA'!I44 -> -0.52508173 | I37: =LN('RAW DATA'!E45) -> 30.541807 | J37: ='RAW DATA'!K45/'RAW DATA'!J45 -> 0.95081986 | K37: =LN('RAW DATA'!O45) -> 3.1354942 | L37: ='RAW DATA'!M45/'RAW DATA'!E45 -> 0.00072718216
A38: BKSL | B38: 2021 | C38: ='RAW DATA'!G46/'RAW DATA'!H46 -> 0.5882997 | D38: ='RAW DATA'!G46/'RAW DATA'!E46 -> 0.3703959 | E38: ='RAW DATA'!L46/'RAW DATA'!H46 -> 0.021864321 | F38: ='RAW DATA'!D46/'RAW DATA'!E46 -> 0.72052655 | G38: ='RAW DATA'!C46/'RAW DATA'!F46 -> 2.8337615 | H38: =('RAW DATA'!I46-'RAW DATA'!I45)/'RAW DATA'!I45 -> 1.0155249 | I38: =LN('RAW DATA'!E46) -> 30.443731 | J38: ='RAW DATA'!K46/'RAW DATA'!J46 -> 0.1802377 | K38: =LN('RAW DATA'!O46) -> 3.1780538 | L38: ='RAW DATA'!M46/'RAW DATA'!E46 -> 0.00070482992
A39: BKSL | B39: 2022 | C39: ='RAW DATA'!G47/'RAW DATA'!H47 -> 0.61982164 | D39: ='RAW DATA'!G47/'RAW DATA'!E47 -> 0.38264808 | E39: ='RAW DATA'!L47/'RAW DATA'!H47 -> -0.016185157 | F39: ='RAW DATA'!D47/'RAW DATA'!E47 -> 0.73198376 | G39: ='RAW DATA'!C47/'RAW DATA'!F47 -> 2.0220317 | H39: =('RAW DATA'!I47-'RAW DATA'!I46)/'RAW DATA'!I46 -> -0.26178394 | I39: =LN('RAW DATA'!E47) -> 30.447732 | J39: ='RAW DATA'!K47/'RAW DATA'!J47 -> 0.054173659 | K39: =LN('RAW DATA'!O47) -> 3.2188758 | L39: ='RAW DATA'!M47/'RAW DATA'!E47 -> 0.00075609176
A40: BKSL | B40: 2023 | C40: ='RAW DATA'!G48/'RAW DATA'!H48 -> 0.31343825 | D40: ='RAW DATA'!G48/'RAW DATA'!E48 -> 0.2386395 | E40: ='RAW DATA'!L48/'RAW DATA'!H48 -> 0.020991197 | F40: ='RAW DATA'!D48/'RAW DATA'!E48 -> 0.82026927 | G40: ='RAW DATA'!C48/'RAW DATA'!F48 -> 1.1677575 | H40: =('RAW DATA'!I48-'RAW DATA'!I47)/'RAW DATA'!I47 -> 1.5586195 | I40: =LN('RAW DATA'!E48) -> 30.621081 | J40: ='RAW DATA'!K48/'RAW DATA'!J48 -> 0.085304767 | K40: =LN('RAW DATA'!O48) -> 3.2580965 | L40: ='RAW DATA'!M48/'RAW DATA'!E48 -> 0.00082457669
...
